Workbook

Sheet diseqc_cntrl_bom
A1: Reference | B1: Qty | C1: Value | D1: DNP | E1: Exclude from BOM | F1: Exclude from Board | G1: Footprint | H1: Datasheet | I1: Mouser Part Number | J1: My Stock | K1: Bag ID | L1: Alternative | M1: Alt Stock | N1: Notes
A2: C1,C3,C5,C33 | B2: 4 | C2: 10u | G2: Capacitor_SMD:C_0603_1608Metric_Pad1.08x0.95mm_HandSolder | H2: https://datasheets.kyocera-avx.com/cx5r.pdf | I2: 581-KGM15CR51E106MT | J2: 20 | K2: 1
A3: C2,C21,C22,C25 | B3: 4 | C3: 2.2u | G3: Capacitor_SMD:C_0603_1608Metric_Pad1.08x0.95mm_HandSolder | H3: https://www.mouser.co.uk/datasheet/3/76/1/GRM188R6YA225MA12-04A.pdf | I3: 81-GRM188R6YA225MA2D | J3: 20 | K3: 2
A4: C4,C7,C10 | B4: 3 | C4: 1u | G4: Capacitor_SMD:C_0603_1608Metric_Pad1.08x0.95mm_HandSolder | H4: https://pim.murata.com/asset/pim4/ceramicCapacitorSMD/GRM188R61A105KA61-01A-EN_PDF_CERAMICCAPACITORSMD | I4: 81-GRM39R105K10 | J4: 15 | K4: 3
A5: C6 | B5: 1 | C5: 10u 25V | G5: LIB_865080440002:CAPAE400X550N | H5: https://www.we-online.com/components/products/download/3D_WCAP-ASLI_4x5+%28rev1%29.pdf | I5: 710-865080440002 | J5: 5 | K5: 4
A6: C8,C31 | B6: 2 | C6: 4.7u | G6: Capacitor_SMD:C_0603_1608Metric_Pad1.08x0.95mm_HandSolder | H6: https://www.mouser.com/catalog/specsheets/taiyo%20yuden_12132018_mlcc11_hq_e.pdf | I6: 963-JMK107BJ475KAHT | J6: 10 | K6: 5
A7: C9,C11,C12,C14,C16,C17,C19,C20,C32,C34,C36,C38,C39,C40,C41 | B7: 15 | C7: 100n | G7: Capacitor_SMD:C_0603_1608Metric_Pad1.08x0.95mm_HandSolder | H7: https://pim.murata.com/asset/pim4/ceramicCapacitorSMD/GRM188R71C104KA01-01-EN_PDF_CERAMICCAPACITORSMD | I7: 81-GRM39X104K16 | J7: 0 | L7: GRM188R71C104KA01D | M7: 50 | N7: Binder
A8: C13 | B8: 1 | C8: 10n | G8: Capacitor_SMD:C_0603_1608Metric_Pad1.08x0.95mm_HandSolder | H8: https://www.mouser.co.uk/datasheet/3/76/2/GRM188R71H103KA01_01.pdf | I8: 81-GRM39X103K50D | J8: 0 | L8: GRM188R71H103KA01D | M8: 25 | N8: Binder
A9: C15,C18,C35,C37 | B9: 4 | C9: 18p | G9: Capacitor_SMD:C_0603_1608Metric_Pad1.08x0.95mm_HandSolder | H9: https://www.mouser.co.uk/datasheet/3/5926/1/C0GNP0_Dielectric.pdf | I9: 581-06031A180CAT2A | J9: 20 | K9: 6
A10: C23 | B10: 1 | C10: 1n | G10: Capacitor_SMD:C_0603_1608Metric_Pad1.08x0.95mm_HandSolder | H10: https://www.mouser.co.uk/datasheet/3/76/1/GRM188R71H102KA01-01.pdf | I10: 81-GRM39X102K050 | J10: 0 | L10: GRM188R71H102KA01D | M10: 25 | N10: Binder
A11: C24,C26 | B11: 2 | C11: 100u | G11: LIB_865080445010:CAPAE660X770N | H11: https://www.we-online.com/components/products/datasheet/865080445010.pdf | I11: 710-865080445010 | J11: 10 | K11: 7
A12: C27 | B12: 1 | C12: 200n | G12: Capacitor_SMD:C_0603_1608Metric_Pad1.08x0.95mm_HandSolder | H12: https://www.mouser.co.uk/datasheet/3/317/1/WTC_MLCC_General_Purpose.pdf | I12: 791-0603B204K160CT | J12: 15 | K12: 8
A13: C28,C30 | B13: 2 | C13: 220n | G13: Capacitor_SMD:C_0603_1608Metric_Pad1.08x0.95mm_HandSolder | H13: https://www.mouser.co.uk/datasheet/3/317/1/WTC_MLCC_General_Purpose.pdf | I13: 791-0603B204K160CT | J13: 15 | K13: 8
A14: C29 | B14: 1 | C14: 220p C0G(NP0) | G14: GRM1885C2A221JA01D:CAPC1608X90N | H14: https://componentsearchengine.com/Datasheets/1/GRM1885C2A221JA01D.pdf | I14: 81-GRM185C2A221JA01D | J14: 5 | K14: 9
A15: C42 | B15: 1 | C15: 22n | G15: Capacitor_SMD:C_0603_1608Metric_Pad1.08x0.95mm_HandSolder | H15: https://www.mouser.co.uk/datasheet/3/72/1/C0603C223K4RACTU.pdf | I15: 80-C0603C223K4R | J15: 5 | K15: 10
A16: D1 | B16: 1 | C16: SS14F-HF | G16: LIB_SS14_HF:SODFL4626X120N | H16: https://www.mouser.it/datasheet/2/80/20190806172716-1729195.pdf | I16: 750-SS14F-HF | J16: 5 | K16: 11
A17: D2 | B17: 1 | C17: SMBJ24D-M3_H | G17: LIB_SMBJ24D-M3_H:DIOM5436X244N | H17: https://www.vishay.com/docs/87606/smbj5cdthrusmbj120cd.pdf | I17: 78-SMBJ24D-M3H | J17: 5 | K17: 12
A18: D3 | B18: 1 | C18: LED_Small | G18: LED_SMD:LED_0603_1608Metric_Pad1.05x0.95mm_HandSolder | H18: https://www.mouser.co.uk/datasheet/3/308/1/APG1608ZGC.pdf | I18: 604-APG1608ZGC | J18: 5 | K18: 36
A19: D4 | B19: 1 | C19: STPS130A | G19: STPS130A:STTH2R02AY | H19: https://www.st.com/resource/en/datasheet/stps130.pdf | I19: 511-STPS130A | J19: 5 | K19: 13
A20: D5 | B20: 1 | C20: US1A | G20: Diode_SMD:D_SMA-SMB_Universal_Handsoldering | H20: https://www.diodes.com/assets/Datasheets/ds16008.pdf | I20: 637-US1A | J20: 5 | K20: 14
A21: D6 | B21: 1 | C21: BAT43XV2 | G21: LIB_BAT43XV2:SODFL1608X70N | H21: http://www.vishay.com/docs/85660/bat42.pdf | I21: 512-BAT43XV2 | J21: 5 | K21: 15
A22: D7 | B22: 1 | C22: RCLAMP0502BATCT | G22: RCLAMP0502BATCT:SOT50P160X90-3N | H22: https://rs.componentsearchengine.com/Datasheets/1/RCLAMP0502BATCT.pdf | I22: 947-RCLAMP0502BATCT | J22: 5 | K22: 16
... A39: L5 | B39: 1 | C39: 0603DC-27NXJRW | G39: 0603DC-27NXJRW:0603DC27NXJRW | H39: https://www.coilcraft.com/getmedia/f3d98f97-cbe2-41fa-b3a9-518f674e881e/0603dc.pdf | I39: 994-0603DC-27NXJRW | J39: 5 | K39: 34
A40: NT1,NT2 | B40: 2 | C40: NetTie_2 | E40: Excluded from BOM | G40: NetTie:NetTie-2_SMD_Pad2.0mm | H40: ~ | J40: 1000
A41: PS1 | B41: 1 | C41: TPS560430X3FDBVT | G41: SOT95P280X145-6N | H41: https://www.ti.com/lit/ds/symlink/tps560430.pdf | I41: 595-TPS560430X3FDBVT | J41: 5 | K41: 26
A42: R1,R16 | B42: 2 | C42: 100k | G42: Resistor_SMD:R_0603_1608Metric_Pad0.98x0.95mm_HandSolder | H42: https://www.mouser.com/catalog/specsheets/YAGEO_PYu_RC_Group_51_RoHS_L_12.pdf | I42: 603-RC0603JR-07100KL | J42: 10 | K42: 51 | L42: RC0603 JR-07 100K | M42: 50 | N42: Alt stock in binder
A43: R2 | B43: 1 | C43: 61k9 1% | G43: Resistor_SMD:R_0603_1608Metric_Pad0.98x0.95mm_HandSolder | H43: https://www.mouser.com/catalog/specsheets/YAGEO_PYu_RC_Group_51_RoHS_L_12.pdf?_gl=1*1qp9l20*_gcl_au*MTI3NDQ0Mzk2NC4xNzY2NDEzNTk1LjIwMzY5MzAxODkuMTc3MDA1MDY4MS4xNzcwMDU3NTMx*_ga*MTk2NjYzNzAxOS4xNzU4NjIyMzM4*_ga_15W4STQT4T*czE3NzAwNTA2ODAkbzI0JGcxJHQxNzcwMDU3NTQwJGozNCRsMCRoMA.. | I43: 603-RC0603FR-0761K9L | J43: 5 | K43: 55
A44: R3 | B44: 1 | C44: 20k 1% | G44: Resistor_SMD:R_0603_1608Metric_Pad0.98x0.95mm_HandSolder | H44: https://www.mouser.com/catalog/specsheets/YAGEO_PYu_RC_Group_51_RoHS_L_12.pdf | I44: 603-RC0603FR-1320KL | J44: 5 | K44: 52
A45: R4 | B45: 1 | C45: 243k 1% | G45: Resistor_SMD:R_0603_1608Metric_Pad0.98x0.95mm_HandSolder | H45: https://www.mouser.com/catalog/specsheets/YAGEO_PYu_RC_Group_51_RoHS_L_12.pdf?_gl=1*1ninmyl*_gcl_au*MTI3NDQ0Mzk2NC4xNzY2NDEzNTk1LjIwMzY5MzAxODkuMTc3MDA1MDY4MS4xNzcwMDU2OTY5*_ga*MTk2NjYzNzAxOS4xNzU4NjIyMzM4*_ga_15W4STQT4T*czE3NzAwNTA2ODAkbzI0JGcxJHQxNzcwMDU2OTgzJGoyNyRsMCRoMA.. | I45: 603-RC0603FR-07243KL | J45: 5 | K45: 49
A46: R5 | B46: 1 | C46: 22k1 1% | G46: Resistor_SMD:R_0603_1608Metric_Pad0.98x0.95mm_HandSolder | H46: https://www.mouser.co.uk/datasheet/3/508/1/PYu-RC_Group_51_RoHS_L_12.pdf | I46: 603-RC0603FR-1322K1L | J46: 5 | K46: 54
A47: R6,R13,R17,R19 | B47: 4 | C47: 10k | G47: Resistor_SMD:R_0603_1608Metric_Pad0.98x0.95mm_HandSolder | H47: https://www.mouser.co.uk/datasheet/3/508/1/PYu-RC_Group_51_RoHS_L_12.pdf | I47: 603-RC0603DR-0710KL | J47: 20 | K47: 46 | L47: RC0603 JR-07 10K | M47: 100 | N47: Alt stock in binder
A48: R7,R8,R12,R20 | B48: 4 | C48: 4k7 | G48: Resistor_SMD:R_0603_1608Metric_Pad0.98x0.95mm_HandSolder | H48: https://www.mouser.co.uk/datasheet/3/508/1/PYU_AC_51_ROHS_L.pdf | I48: 603-AC0603FR-074K7L | J48: 20 | K48: 43
A49: R9,R10 | B49: 2 | C49: 2k7 | G49: Resistor_SMD:R_0603_1608Metric_Pad0.98x0.95mm_HandSolder | H49: https://www.mouser.co.uk/datasheet/3/508/1/PYu-AR_51_RoHS_L_7.pdf | I49: 603-AR0603JR-072K7L | J49: 10 | K49: 41 | L49: RC0603 JR-07 2K7 | M49: 50 | N49: Alt stock in binder
A50: R11 | B50: 1 | C50: 1k5 | G50: Resistor_SMD:R_0603_1608Metric_Pad0.98x0.95mm_HandSolder | H50: https://www.mouser.co.uk/datasheet/3/508/1/PYU_AC_51_ROHS_L.pdf | I50: 603-AC0603JR-071K5L | J50: 5 | K50: 40 | L50: RC0603 JR-07 1K5 | M50: 50 | N50: Alt stock in binder
A51: R14,R15 | B51: 2 | C51: 5k1 | G51: Resistor_SMD:R_0603_1608Metric_Pad0.98x0.95mm_HandSolder | H51: https://www.mouser.co.uk/datasheet/3/508/1/pyu-rc_51_rohs_p.pdf | I51: 603-RC0603FR-075K1P | J51: 10 | K51: 50 | L51: RC0603 JR-07 5K1 | M51: 50 | N51: Alt stock in binder
A52: R18 | B52: 1 | C52: 12k4 1% | G52: Resistor_SMD:R_0603_1608Metric_Pad0.98x0.95mm_HandSolder | H52: https://www.mouser.co.uk/datasheet/3/508/1/PYU_AC_51_ROHS_L.pdf | I52: 603-AC0603FR-0712K4L | J52: 5 | K52: 47
A53: R21 | B53: 1 | C53: 1M | G53: Resistor_SMD:R_0603_1608Metric_Pad0.98x0.95mm_HandSolder | H53: https://www.mouser.co.uk/datasheet/3/508/1/PYu-RC_Group_51_RoHS_L_12.pdf | I53: 603-RC0603JR-131ML | J53: 5 | K53: 53 | L53: RC0603 JR-07 1M | M53: 25 | N53: Alt stock in binder
A54: R22 | B54: 1 | C54: 0 | G54: Resistor_SMD:R_0603_1608Metric_Pad0.98x0.95mm_HandSolder | H54: https://www.mouser.com/catalog/specsheets/Yageo_06282023_ACseries.pdf?_gl=1*sklq6b*_gcl_au*MTI3NDQ0Mzk2NC4xNzY2NDEzNTk1LjIwMzY5MzAxODkuMTc3MDA1MDY4MS4xNzcwMDU4MDc5*_ga*MTk2NjYzNzAxOS4xNzU4NjIyMzM4*_ga_15W4STQT4T*czE3NzAwNTA2ODAkbzI0JGcxJHQxNzcwMDU4MDk1JGoyNiRsMCRoMA.. | I54: 603-AC0603JR-130RL | J54: 5 | K54: 48 | L54: RC0603 JR-07 0R | M54: 100 | N54: Alt stock in binder
A55: R23,R24,R25,R26 | B55: 4 | C55: 33r | G55: Resistor_SMD:R_0603_1608Metric_Pad0.98x0.95mm_HandSolder | H55: https://www.te.com/commerce/DocumentDelivery/DDEController?Action=srchrtrv&DocNm=1622922&DocType=Customer+Drawing&DocLang=English&PartCntxt=1622922-1 | I55: 279-CRG0603F33R | J55: 20 | K55: 44 | L55: RC0603 JR-07 330R | M55: 50 | N55: Alt stock in binder
A56: R27,R28 | B56: 2 | C56: 49r9 1% | G56: Resistor_SMD:R_0603_1608Metric_Pad0.98x0.95mm_HandSolder | H56: https://www.mouser.co.uk/datasheet/3/508/1/PYu-AF_51_RoHS_L_9.pdf | I56: 603-AF0603FR-0749R9L | J56: 10 | K56: 45
...

Sheet Stock
A1: Mouser Part Number | B1: Manufacturer Part Number | C1: Value | D1: DNP | E1: Exclude from BOM | F1: Exclude from Board | G1: Datasheet | H1: Stock | I1: Bin/Bag
A2: 581-KGM15CR51E106MT | C2: 10u | G2: https://datasheets.kyocera-avx.com/cx5r.pdf | H2: 20 | I2: 1
A3: 81-GRM188R6YA225MA2D | B3: =VLOOKUP(Table2[[#This Row],[Mouser Part Number]],Map!H3:H58,1) -> 815-ABLS25.MHZDFT | C3: 2.2u | G3: https://www.mouser.co.uk/datasheet/3/76/1/GRM188R6YA225MA12-04A.pdf | H3: 20 | I3: 2
A4: 81-GRM39R105K10 | B4: =VLOOKUP(Table2[[#This Row],[Mouser Part Number]],Map!H4:H59,1) -> 815-ABLS25.MHZDFT | C4: 1u | G4: https://pim.murata.com/asset/pim4/ceramicCapacitorSMD/GRM188R61A105KA61-01A-EN_PDF_CERAMICCAPACITORSMD | H4: 15 | I4: 3
A5: 710-865080440002 | B5: =VLOOKUP(Table2[[#This Row],[Mouser Part Number]],Map!H5:H60,1) -> 673-H1102NL | C5: 10u 25V | G5: https://www.we-online.com/components/products/download/3D_WCAP-ASLI_4x5+%28rev1%29.pdf | H5: 5 | I5: 4
A6: 963-JMK107BJ475KAHT | B6: =VLOOKUP(Table2[[#This Row],[Mouser Part Number]],Map!H6:H61,1) -> 815-ABLS25.MHZDFT | C6: 4.7u | G6: https://www.mouser.com/catalog/specsheets/taiyo%20yuden_12132018_mlcc11_hq_e.pdf | H6: 10 | I6: 5
A7: 81-GRM39X104K16 | B7: =VLOOKUP(Table2[[#This Row],[Mouser Part Number]],Map!H7:H62,1) -> 815-ABLS25.MHZDFT | C7: 100n | G7: https://pim.murata.com/asset/pim4/ceramicCapacitorSMD/GRM188R71C104KA01-01-EN_PDF_CERAMICCAPACITORSMD | H7: 0
A8: 81-GRM39X103K50D | B8: =VLOOKUP(Table2[[#This Row],[Mouser Part Number]],Map!H8:H63,1) -> 815-ABLS25.MHZDFT | C8: 10n | G8: https://www.mouser.co.uk/datasheet/3/76/2/GRM188R71H103KA01_01.pdf | H8: 0
A9: 581-06031A180CAT2A | B9: =VLOOKUP(Table2[[#This Row],[Mouser Part Number]],Map!H9:H64,1) -> 200-TMM10501TSSM | C9: 18p | G9: https://www.mouser.co.uk/datasheet/3/5926/1/C0GNP0_Dielectric.pdf | H9: 20 | I9: 6
A10: 81-GRM39X102K050 | B10: =VLOOKUP(Table2[[#This Row],[Mouser Part Number]],Map!H10:H65,1) -> 815-ABLS25.MHZDFT | C10: 1n | G10: https://www.mouser.co.uk/datasheet/3/76/1/GRM188R71H102KA01-01.pdf | H10: 0
A11: 710-865080445010 | B11: =VLOOKUP(Table2[[#This Row],[Mouser Part Number]],Map!H11:H66,1) -> 673-H1102NL | C11: 100u | G11: https://www.we-online.com/components/products/datasheet/865080445010.pdf | H11: 10 | I11: 7
A12: 791-0603B204K160CT | B12: =VLOOKUP(Table2[[#This Row],[Mouser Part Number]],Map!H12:H67,1) -> 673-H1102NL | C12: 200n | G12: https://www.mouser.co.uk/datasheet/3/317/1/WTC_MLCC_General_Purpose.pdf | H12: 15 | I12: 8
A13: 791-0603B204K160CT | B13: =VLOOKUP(Table2[[#This Row],[Mouser Part Number]],Map!H13:H68,1) -> 673-H1102NL | C13: 220n | G13: https://www.mouser.co.uk/datasheet/3/317/1/WTC_MLCC_General_Purpose.pdf | H13: 15 | I13: 8
A14: 81-GRM185C2A221JA01D | B14: =VLOOKUP(Table2[[#This Row],[Mouser Part Number]],Map!H14:H69,1) -> 815-ABLS25.MHZDFT | C14: 220p C0G(NP0) | G14: https://componentsearchengine.com/Datasheets/1/GRM1885C2A221JA01D.pdf | H14: 5 | I14: 9
A15: 80-C0603C223K4R | B15: =VLOOKUP(Table2[[#This Row],[Mouser Part Number]],Map!H15:H70,1) -> 673-H1102NL | C15: 22n | G15: https://www.mouser.co.uk/datasheet/3/72/1/C0603C223K4RACTU.pdf | H15: 5 | I15: 10
A16: 750-SS14F-HF | B16: =VLOOKUP(Table2[[#This Row],[Mouser Part Number]],Map!H16:H71,1) -> 673-H1102NL | C16: SS14F-HF | G16: https://www.mouser.it/datasheet/2/80/20190806172716-1729195.pdf | H16: 5 | I16: 11
A17: 78-SMBJ24D-M3H | B17: =VLOOKUP(Table2[[#This Row],[Mouser Part Number]],Map!H17:H72,1) -> 673-H1102NL | C17: SMBJ24D-M3_H | G17: https://www.vishay.com/docs/87606/smbj5cdthrusmbj120cd.pdf | H17: 5 | I17: 12
A18: 604-APG1608ZGC | B18: =VLOOKUP(Table2[[#This Row],[Mouser Part Number]],Map!H18:H73,1) -> 603-AC0603FR-13470RL | C18: LED_Small | G18: https://www.mouser.co.uk/datasheet/3/308/1/APG1608ZGC.pdf | H18: 5 | I18: 36
A19: 511-STPS130A | B19: =VLOOKUP(Table2[[#This Row],[Mouser Part Number]],Map!H19:H74,1) -> 200-TSW10523TD | C19: STPS130A | G19: https://www.st.com/resource/en/datasheet/stps130.pdf | H19: 5 | I19: 13
A20: 637-US1A | B20: =VLOOKUP(Table2[[#This Row],[Mouser Part Number]],Map!H20:H75,1) -> 611-PCM12SMTBR | C20: US1A | G20: https://www.diodes.com/assets/Datasheets/ds16008.pdf | H20: 5 | I20: 14
A21: 512-BAT43XV2 | B21: =VLOOKUP(Table2[[#This Row],[Mouser Part Number]],Map!H21:H76,1) -> 200-TSW10523TD | C21: BAT43XV2 | G21: http://www.vishay.com/docs/85660/bat42.pdf | H21: 5 | I21: 15
A22: 947-RCLAMP0502BATCT | B22: =VLOOKUP(Table2[[#This Row],[Mouser Part Number]],Map!H22:H77,1) -> 815-ABLS25.MHZDFT | C22: RCLAMP0502BATCT | G22: https://rs.componentsearchengine.com/Datasheets/1/RCLAMP0502BATCT.pdf | H22: 5 | I22: 16
... A52: 603-RC0603JR-131ML | B52: =VLOOKUP(Table2[[#This Row],[Mouser Part Number]],Map!H52:H107,1) -> 603-AC0603FR-13470RL | C52: 1M | G52: https://www.mouser.co.uk/datasheet/3/508/1/PYu-RC_Group_51_RoHS_L_12.pdf | H52: 5 | I52: 53
A53: 603-AC0603JR-130RL | B53: =VLOOKUP(Table2[[#This Row],[Mouser Part Number]],Map!H53:H108,1) -> 603-AC0603FR-13470RL | C53: 0 | G53: https://www.mouser.com/catalog/specsheets/Yageo_06282023_ACseries.pdf?_gl=1*sklq6b*_gcl_au*MTI3NDQ0Mzk2NC4xNzY2NDEzNTk1LjIwMzY5MzAxODkuMTc3MDA1MDY4MS4xNzcwMDU4MDc5*_ga*MTk2NjYzNzAxOS4xNzU4NjIyMzM4*_ga_15W4STQT4T*czE3NzAwNTA2ODAkbzI0JGcxJHQxNzcwMDU4MDk1JGoyNiRsMCRoMA.. | H53: 5 | I53: 48
A54: 279-CRG0603F33R | B54: =VLOOKUP(Table2[[#This Row],[Mouser Part Number]],Map!H54:H109,1) -> #N/A | C54: 33r | G54: https://www.te.com/commerce/DocumentDelivery/DDEController?Action=srchrtrv&DocNm=1622922&DocType=Customer+Drawing&DocLang=English&PartCntxt=1622922-1 | H54: 20 | I54: 44
A55: 603-AF0603FR-0749R9L | B55: =VLOOKUP(Table2[[#This Row],[Mouser Part Number]],Map!H55:H110,1) -> #N/A | C55: 49r9 1% | G55: https://www.mouser.co.uk/datasheet/3/508/1/PYu-AF_51_RoHS_L_9.pdf | H55: 10 | I55: 45
A56: 603-AC0603FR-13470RL | B56: =VLOOKUP(Table2[[#This Row],[Mouser Part Number]],Map!H56:H111,1) -> #N/A | C56: 470r | G56: https://www.mouser.co.uk/datasheet/3/508/1/PYu-AC_51_RoHS_L_11.pdf | H56: 10 | I56: 42
A57: 611-PCM12SMTBR | B57: =VLOOKUP(Table2[[#This Row],[Mouser Part Number]],Map!H57:H112,1) -> #N/A | C57: PCM12SMTBR | G57: https://www.ckswitches.com/media/1424/pcm.pdf | H57: 5 | I57: 21
A58: 673-H1102NL | B58: =VLOOKUP(Table2[[#This Row],[Mouser Part Number]],Map!H58:H113,1) -> #N/A | C58: H1102NL | G58: https://productfinder.pulseeng.com/products/datasheets/h1102nl.pdf | H58: 5 | I58: 18
A59: 815-LS8000MHZ20B3HT | B59: =VLOOKUP(Table2[[#This Row],[Mouser Part Number]],Map!H59:H114,1) -> #N/A | C59: 8MHZ | G59: https://abracon.com/Resonators/abls.pdf | H59: 5 | I59: 20
A60: 815-ABLS25.MHZDFT | B60: =VLOOKUP(Table2[[#This Row],[Mouser Part Number]],Map!H60:H115,1) -> #N/A | C60: 25MHZ | G60: https://abracon.com/Resonators/abls.pdf | H60: 5 | I60: 27
B61: GRM188R71C104KA01D | H61: 50
B62: GRM188R71H103KA01D | H62: 25
B63: GRM188R71H102KA01D | H63: 25
B64: RC0603 JR-07 100K | H64: 50
B65: RC0603 JR-07 10K | H65: 50
B66: RC0603 JR-07 2K7 | H66: 50
B67: RC0603 JR-07 1K5 | H67: 50
B68: RC0603 JR-07 5K1 | H68: 50
B69: RC0603 JR-07 1M | H69: 25
...

Sheet Map
A1: Mfr. No: | B1: Sales Order No: | C1: Web Order No: | D1: PO Number: | E1: Line No. | F1: Order Date: | G1: Order Status: | H1: Mouser No: | I1: Desc.: | J1: Customer No | K1: Order Qty. | L1: Ext. (GBP) | M1: Price (GBP) | N1: Status | O1: Date | P1: Invoice No. | Q1: Tariff: Price (GBP) | R1: Tariff: Ext. (GBP)
A2: L7805CV | B2: 278656763 | C2: 38215913 | D2: 38215913 | E2: 1 | F2: 08-Feb-26 | G2: Complete | H2: 511-L7805CV | I2: Linear Voltage Regulators Linear Voltage Regulators 5.0V 1.5A Positive | K2: 8 | L2: £0.375 | M2: £0.375 | N2: 8 Shipped | O2: 09-Feb-26 | P2: 88693173
A3: KGM15CR51E106MT | B3: 278656763 | C3: 38215913 | D3: 38215913 | E3: 2 | F3: 08-Feb-26 | G3: Complete | H3: 581-KGM15CR51E106MT | I3: Multilayer Ceramic Capacitors MLCC - SMD/SMT Multilayer Ceramic Capacitors MLCC - SMD/SMT 25V 10uF X5R 0603 20 % | K3: 20 | L3: £0.227 | M3: £0.227 | N3: 20 Shipped | O3: 09-Feb-26 | P3: 88693173
A4: GRM188R6YA225MA12D | B4: 278656763 | C4: 38215913 | D4: 38215913 | E4: 3 | F4: 08-Feb-26 | G4: Complete | H4: 81-GRM188R6YA225MA2D | I4: Multilayer Ceramic Capacitors MLCC - SMD/SMT Multilayer Ceramic Capacitors MLCC - SMD/SMT 2.2 uF 35 VDC 20% 0603 X5R | K4: 20 | L4: £0.029 | M4: £0.029 | N4: 20 Shipped | O4: 09-Feb-26 | P4: 88693173
A5: GRM188R61A105KA61D | B5: 278656763 | C5: 38215913 | D5: 38215913 | E5: 4 | F5: 08-Feb-26 | G5: Complete | H5: 81-GRM39R105K10 | I5: Multilayer Ceramic Capacitors MLCC - SMD/SMT Multilayer Ceramic Capacitors MLCC - SMD/SMT 1 uF 10 VDC 10% 0603 X5R | K5: 15 | L5: £0.036 | M5: £0.036 | N5: 15 Shipped | O5: 09-Feb-26 | P5: 88693173
A6: 865080440002 | B6: 278656763 | C6: 38215913 | D6: 38215913 | E6: 5 | F6: 08-Feb-26 | G6: Complete | H6: 710-865080440002 | I6: Aluminium Electrolytic Capacitors - SMD Aluminium Electrolytic Capacitors - SMD WCAP-ASLI 10uF 25V 20% SMD/SMT | K6: 5 | L6: £0.142 | M6: £0.142 | N6: 5 Shipped | O6: 09-Feb-26 | P6: 88693173
A7: JMK107BJ475KAHT | B7: 278656763 | C7: 38215913 | D7: 38215913 | E7: 6 | F7: 08-Feb-26 | G7: Complete | H7: 963-JMK107BJ475KAHT | I7: Multilayer Ceramic Capacitors MLCC - SMD/SMT Multilayer Ceramic Capacitors MLCC - SMD/SMT 963-MCASJ168SB5475KT RPLCMT PN 6.3V 4.7uF X5R 0603 AEC-Q200 | K7: 10 | L7: £0.035 | M7: £0.035 | N7: 10 Shipped | O7: 09-Feb-26 | P7: 88693173
A8: 06031A180CAT2A | B8: 278656763 | C8: 38215913 | D8: 38215913 | E8: 7 | F8: 08-Feb-26 | G8: Complete | H8: 581-06031A180CAT2A | I8: Multilayer Ceramic Capacitors MLCC - SMD/SMT Multilayer Ceramic Capacitors MLCC - SMD/SMT 100V 18pF C0G 0603 0 .25pF | K8: 20 | L8: £0.217 | M8: £0.217 | N8: 20 Shipped | O8: 09-Feb-26 | P8: 88693173
A9: 865080445010 | B9: 278656763 | C9: 38215913 | D9: 38215913 | E9: 8 | F9: 08-Feb-26 | G9: Complete | H9: 710-865080445010 | I9: Aluminium Electrolytic Capacitors - SMD Aluminium Electrolytic Capacitors - SMD WCAP-ASLI 100uF 25V 20% SMD/SMT | K9: 10 | L9: £0.248 | M9: £0.248 | N9: 10 Shipped | O9: 09-Feb-26 | P9: 88693173
A10: 0603B204K160CT | B10: 278656763 | C10: 38215913 | D10: 38215913 | E10: 9 | F10: 08-Feb-26 | G10: Complete | H10: 791-0603B204K160CT | I10: Multilayer Ceramic Capacitors MLCC - SMD/SMT Multilayer Ceramic Capacitors MLCC - SMD/SMT 0603 MLCC X7R 0.2 uF, +/- 10% 16 V T&R GP | K10: 15 | L10: £0.052 | M10: £0.052 | N10: 15 Shipped | O10: 09-Feb-26 | P10: 88693173
A11: GRM1885C2A221JA01D | B11: 278656763 | C11: 38215913 | D11: 38215913 | E11: 10 | F11: 08-Feb-26 | G11: Complete | H11: 81-GRM185C2A221JA01D | I11: Multilayer Ceramic Capacitors MLCC - SMD/SMT Multilayer Ceramic Capacitors MLCC - SMD/SMT 220 pF 100 VDC 5% 0603 C0G (NP0) | K11: 5 | L11: £0.098 | M11: £0.098 | N11: 5 Shipped | O11: 09-Feb-26 | P11: 88693173
A12: C0603C223K4RACTU | B12: 278656763 | C12: 38215913 | D12: 38215913 | E12: 11 | F12: 08-Feb-26 | G12: Complete | H12: 80-C0603C223K4R | I12: Multilayer Ceramic Capacitors MLCC - SMD/SMT Multilayer Ceramic Capacitors MLCC - SMD/SMT 16V 0.022uF X7R 0603 10% | K12: 5 | L12: £0.075 | M12: £0.075 | N12: 5 Shipped | O12: 09-Feb-26 | P12: 88693173
A13: SS14F-HF | B13: 278656763 | C13: 38215913 | D13: 38215913 | E13: 12 | F13: 08-Feb-26 | G13: Complete | H13: 750-SS14F-HF | I13: Schottky Diodes & Rectifiers Schottky Diodes & Rectifiers DIODE SCHOTTKY 1A 40V SMAF | K13: 5 | L13: £0.165 | M13: £0.165 | N13: 5 Shipped | O13: 09-Feb-26 | P13: 88693173
... A57: ABLS-25.000MHZ-D-FT | B57: 278656763 | C57: 38215913 | D57: 38215913 | E57: 56 | F57: 08-Feb-26 | G57: Complete | H57: 815-ABLS25.MHZDFT | I57: Crystals Crystals 25.0 MHZ 18PF 50PPM 40 OHMS | K57: 5 | L57: £0.21 | M57: £0.21 | N57: 5 Shipped | O57: 09-Feb-26 | P57: 88693173
